Workbook

Sheet Οδηγίες
A1: ΔΙΠΛΟΓΡΑΦΙΚΑ ΒΙΒΛΙΑ ΕΓΛΣ — Πρακτικό Εργαλείο
A2: Θεωρία + ζωντανά παραδείγματα σε Excel • για αρχάριους
A4: ΤΙ ΕΙΝΑΙ ΑΥΤΟ ΤΟ ΑΡΧΕΙΟ
A5: Ένα ολοκληρωμένο, ζωντανό μοντέλο διπλογραφικής λογιστικής. Γράφεις εγγραφές στο ΗΜΕΡΟΛΟΓΙΟ και
A6: το ΙΣΟΖΥΓΙΟ και το ΚΑΘΟΛΙΚΟ ενημερώνονται ΑΥΤΟΜΑΤΑ με τύπους. Δες πώς "κουμπώνουν" όλα μεταξύ τους.
A8: ΤΑ ΦΥΛΛΑ (καρτέλες κάτω)
A9: 1) Σχέδιο Λογαριασμών → Η λίστα των λογαριασμών ΕΓΛΣ (κωδικός + περιγραφή + είδος).
A10: 2) Ημερολόγιο → ΕΔΩ ΓΡΑΦΕΙΣ. Κάθε συναλλαγή = γραμμές με Χρέωση & Πίστωση που ισοσκελίζουν.
A11: 3) Ισοζύγιο → Αθροίζει αυτόματα κάθε λογαριασμό. Ελέγχει ότι Σ.Χρέωσης = Σ.Πίστωσης.
A12: 4) Καθολικό (Τ) → Δείχνει τους βασικούς λογαριασμούς σε μορφή "Τ" (αριστερά Χρέωση, δεξιά Πίστωση).
A13: 5) Ασκήσεις → 5 συναλλαγές για εξάσκηση, με λύσεις από κάτω.
A15: ΠΩΣ ΝΑ ΤΟ ΧΡΗΣΙΜΟΠΟΙΗΣΕΙΣ (3 βήματα)
... A23: ΥΠΟΜΝΗΜΑ ΧΡΩΜΑΤΩΝ
B24: Κίτρινο = κελιά που ΣΥΜΠΛΗΡΩΝΕΙΣ εσύ (εγγραφές)
B25: Γαλάζιο = επικεφαλίδες / τίτλοι
B26: Πράσινο = αυτόματα αθροίσματα & έλεγχοι (μην τα πειράζεις)
B27: Λευκό = τύποι που υπολογίζονται μόνοι τους
A29: Σημείωση: Οι κωδικοί ακολουθούν το ΕΓΛΣ, που παραμένει η βάση κωδικοποίησης και στα σημερινά ΕΛΠ (Ν.4308/2014).

Sheet Σχέδιο Λογαριασμών
A1: ΣΧΕΔΙΟ ΛΟΓΑΡΙΑΣΜΩΝ (ΕΓΛΣ)
A2: Αντιπροσωπευτικοί λογαριασμοί ανά ομάδα • «Είδος» = φύση λογαριασμού
A4: Κωδικός | B4: Περιγραφή Λογαριασμού | C4: Ομάδα | D4: Είδος | E4: Κανονικό Υπόλοιπο
A5: 10.00 | B5: Εδαφικές εκτάσεις (Γήπεδα-Οικόπεδα) | C5: 1. Πάγιο ενεργητικό | D5: Ενεργητικό | E5: Χρεωστικό
A6: 11.00 | B6: Κτίρια - Εγκαταστάσεις κτιρίων | C6: 1. Πάγιο ενεργητικό | D6: Ενεργητικό | E6: Χρεωστικό
A7: 12.00 | B7: Μηχανήματα - Τεχνικές εγκαταστάσεις | C7: 1. Πάγιο ενεργητικό | D7: Ενεργητικό | E7: Χρεωστικό
A8: 13.00 | B8: Μεταφορικά μέσα | C8: 1. Πάγιο ενεργητικό | D8: Ενεργητικό | E8: Χρεωστικό
A9: 14.00 | B9: Έπιπλα και λοιπός εξοπλισμός | C9: 1. Πάγιο ενεργητικό | D9: Ενεργητικό | E9: Χρεωστικό
A10: 16.00 | B10: Ασώματες ακινητοποιήσεις (άυλα) | C10: 1. Πάγιο ενεργητικό | D10: Ενεργητικό | E10: Χρεωστικό
A11: 20.00 | B11: Εμπορεύματα | C11: 2. Αποθέματα | D11: Ενεργητικό | E11: Χρεωστικό
A12: 24.00 | B12: Πρώτες & βοηθητικές ύλες | C12: 2. Αποθέματα | D12: Ενεργητικό | E12: Χρεωστικό
A13: 30.00 | B13: Πελάτες | C13: 3. Απαιτήσεις & Διαθέσιμα | D13: Ενεργητικό | E13: Χρεωστικό
A14: 33.00 | B14: Χρεώστες διάφοροι | C14: 3. Απαιτήσεις & Διαθέσιμα | D14: Ενεργητικό | E14: Χρεωστικό
A15: 38.00 | B15: Ταμείο | C15: 3. Απαιτήσεις & Διαθέσιμα | D15: Ενεργητικό | E15: Χρεωστικό
... A40: 86.00 | B40: Αποτελέσματα χρήσεως | C40: 8. Αποτελέσματα | D40: Αποτέλεσμα | E40: —

Sheet Ημερολόγιο
A1: ΗΜΕΡΟΛΟΓΙΟ (Βιβλίο πρώτης εγγραφής)
A2: Γράψε τον Κωδικό και το όνομα του λογαριασμού μπαίνει μόνο του • Κάθε εγγραφή πρέπει να ισοσκελίζει
A4: Α/Α | B4: Ημ/νία | C4: Παραστατικό | D4: Αιτιολογία | E4: Κωδικός Λογ/σμού | F4: Λογαριασμός (αυτόματο) | G4: Χρέωση | H4: Πίστωση
A5: 1 | B5: 01/06/2025 | C5: — | D5: Έναρξη: εισφορά κεφαλαίου (μετρητά + τράπεζα) | E5: 38.00 | F5: =IFERROR(INDEX('Σχέδιο Λογαριασμών'!$B$5:$B$40,MATCH(E5,'Σχέδιο Λογαριασμών'!$A$5:$A$40,0)),"") -> Ταμείο | G5: 5000
E6: 38.03 | F6: =IFERROR(INDEX('Σχέδιο Λογαριασμών'!$B$5:$B$40,MATCH(E6,'Σχέδιο Λογαριασμών'!$A$5:$A$40,0)),"") -> Καταθέσεις όψεως (Τράπεζα) | G6: 20000
E7: 40.00 | F7: =IFERROR(INDEX('Σχέδιο Λογαριασμών'!$B$5:$B$40,MATCH(E7,'Σχέδιο Λογαριασμών'!$A$5:$A$40,0)),"") -> Κεφάλαιο | H7: 25000
A8: 2 | B8: 03/06/2025 | C8: ΤΙΜ.Α-101 | D8: Αγορά ραφιών/εξοπλισμού με ΦΠΑ 24%, επί πιστώσει | E8: 14.00 | F8: =IFERROR(INDEX('Σχέδιο Λογαριασμών'!$B$5:$B$40,MATCH(E8,'Σχέδιο Λογαριασμών'!$A$5:$A$40,0)),"") -> Έπιπλα και λοιπός εξοπλισμός | G8: 2000
E9: 54.00 | F9: =IFERROR(INDEX('Σχέδιο Λογαριασμών'!$B$5:$B$40,MATCH(E9,'Σχέδιο Λογαριασμών'!$A$5:$A$40,0)),"") -> Φ.Π.Α. | G9: 480
E10: 50.00 | F10: =IFERROR(INDEX('Σχέδιο Λογαριασμών'!$B$5:$B$40,MATCH(E10,'Σχέδιο Λογαριασμών'!$A$5:$A$40,0)),"") -> Προμηθευτές | H10: 2480
A11: 3 | B11: 05/06/2025 | C11: ΤΙΜ.Α-215 | D11: Αγορά εμπορευμάτων με ΦΠΑ 24%, επί πιστώσει | E11: 20.00 | F11: =IFERROR(INDEX('Σχέδιο Λογαριασμών'!$B$5:$B$40,MATCH(E11,'Σχέδιο Λογαριασμών'!$A$5:$A$40,0)),"") -> Εμπορεύματα | G11: 10000
E12: 54.00 | F12: =IFERROR(INDEX('Σχέδιο Λογαριασμών'!$B$5:$B$40,MATCH(E12,'Σχέδιο Λογαριασμών'!$A$5:$A$40,0)),"") -> Φ.Π.Α. | G12: 2400
E13: 50.00 | F13: =IFERROR(INDEX('Σχέδιο Λογαριασμών'!$B$5:$B$40,MATCH(E13,'Σχέδιο Λογαριασμών'!$A$5:$A$40,0)),"") -> Προμηθευτές | H13: 12400
A14: 4 | B14: 10/06/2025 | C14: ΤΙΜ.Π-1 | D14: Πώληση εμπορευμάτων με ΦΠΑ 24%, επί πιστώσει | E14: 30.00 | F14: =IFERROR(INDEX('Σχέδιο Λογαριασμών'!$B$5:$B$40,MATCH(E14,'Σχέδιο Λογαριασμών'!$A$5:$A$40,0)),"") -> Πελάτες | G14: 9920
E15: 70.00 | F15: =IFERROR(INDEX('Σχέδιο Λογαριασμών'!$B$5:$B$40,MATCH(E15,'Σχέδιο Λογαριασμών'!$A$5:$A$40,0)),"") -> Πωλήσεις εμπορευμάτων | H15: 8000
E16: 54.00 | F16: =IFERROR(INDEX('Σχέδιο Λογαριασμών'!$B$5:$B$40,MATCH(E16,'Σχέδιο Λογαριασμών'!$A$5:$A$40,0)),"") -> Φ.Π.Α. | H16: 1920
A17: 5 | B17: 12/06/2025 | C17: Ζ-report | D17: Λιανική πώληση τοις μετρητοίς με ΦΠΑ 24% | E17: 38.00 | F17: =IFERROR(INDEX('Σχέδιο Λογαριασμών'!$B$5:$B$40,MATCH(E17,'Σχέδιο Λογαριασμών'!$A$5:$A$40,0)),"") -> Ταμείο | G17: 3720
E18: 70.00 | F18: =IFERROR(INDEX('Σχέδιο Λογαριασμών'!$B$5:$B$40,MATCH(E18,'Σχέδιο Λογαριασμών'!$A$5:$A$40,0)),"") -> Πωλήσεις εμπορευμάτων | H18: 3000
E19: 54.00 | F19: =IFERROR(INDEX('Σχέδιο Λογαριασμών'!$B$5:$B$40,MATCH(E19,'Σχέδιο Λογαριασμών'!$A$5:$A$40,0)),"") -> Φ.Π.Α. | H19: 720
A20: 6 | B20: 15/06/2025 | C20: EXTRAIT | D20: Εξόφληση προμηθευτή (εγγρ.3) με έμβασμα | E20: 50.00 | F20: =IFERROR(INDEX('Σχέδιο Λογαριασμών'!$B$5:$B$40,MATCH(E20,'Σχέδιο Λογαριασμών'!$A$5:$A$40,0)),"") -> Προμηθευτές | G20: 12400
E21: 38.03 | F21: =IFERROR(INDEX('Σχέδιο Λογαριασμών'!$B$5:$B$40,MATCH(E21,'Σχέδιο Λογαριασμών'!$A$5:$A$40,0)),"") -> Καταθέσεις όψεως (Τράπεζα) | H21: 12400
A22: 7 | B22: 18/06/2025 | C22: EXTRAIT | D22: Είσπραξη από πελάτη (εγγρ.4) στην τράπεζα | E22: 38.03 | F22: =IFERROR(INDEX('Σχέδιο Λογαριασμών'!$B$5:$B$40,MATCH(E22,'Σχέδιο Λογαριασμών'!$A$5:$A$40,0)),"") -> Καταθέσεις όψεως (Τράπεζα) | G22: 9920
E23: 30.00 | F23: =IFERROR(INDEX('Σχέδιο Λογαριασμών'!$B$5:$B$40,MATCH(E23,'Σχέδιο Λογαριασμών'!$A$5:$A$40,0)),"") -> Πελάτες | H23: 9920
A24: 8 | B24: 20/06/2025 | C24: ΑΠΟΔ.ΕΝΟΙΚ. | D24: Πληρωμή ενοικίου καταστήματος (χωρίς ΦΠΑ) | E24: 62.04 | F24: =IFERROR(INDEX('Σχέδιο Λογαριασμών'!$B$5:$B$40,MATCH(E24,'Σχέδιο Λογαριασμών'!$A$5:$A$40,0)),"") -> Ενοίκια | G24: 800
E25: 38.00 | F25: =IFERROR(INDEX('Σχέδιο Λογαριασμών'!$B$5:$B$40,MATCH(E25,'Σχέδιο Λογαριασμών'!$A$5:$A$40,0)),"") -> Ταμείο | H25: 800
A26: 9 | B26: 22/06/2025 | C26: ΔΕΗ-0622 | D26: Λογαριασμός ΔΕΗ με ΦΠΑ 24%, επί πιστώσει | E26: 62.98 | F26: =IFERROR(INDEX('Σχέδιο Λογαριασμών'!$B$5:$B$40,MATCH(E26,'Σχέδιο Λογαριασμών'!$A$5:$A$40,0)),"") -> Λοιπές παροχές τρίτων (ΔΕΗ, ύδρευση) | G26: 500
E27: 54.00 | F27: =IFERROR(INDEX('Σχέδιο Λογαριασμών'!$B$5:$B$40,MATCH(E27,'Σχέδιο Λογαριασμών'!$A$5:$A$40,0)),"") -> Φ.Π.Α. | G27: 120
E28: 50.00 | F28: =IFERROR(INDEX('Σχέδιο Λογαριασμών'!$B$5:$B$40,MATCH(E28,'Σχέδιο Λογαριασμών'!$A$5:$A$40,0)),"") -> Προμηθευτές | H28: 620
A29: 10 | B29: 25/06/2025 | C29: ΟΤΕ-0622 | D29: Λογαριασμός τηλεφώνου/internet με ΦΠΑ 24%, μετρητά | E29: 62.03 | F29: =IFERROR(INDEX('Σχέδιο Λογαριασμών'!$B$5:$B$40,MATCH(E29,'Σχέδιο Λογαριασμών'!$A$5:$A$40,0)),"") -> Τηλεπικοινωνίες | G29: 100
E30: 54.00 | F30: =IFERROR(INDEX('Σχέδιο Λογαριασμών'!$B$5:$B$40,MATCH(E30,'Σχέδιο Λογαριασμών'!$A$5:$A$40,0)),"") -> Φ.Π.Α. | G30: 24
E31: 38.00 | F31: =IFERROR(INDEX('Σχέδιο Λογαριασμών'!$B$5:$B$40,MATCH(E31,'Σχέδιο Λογαριασμών'!$A$5:$A$40,0)),"") -> Ταμείο | H31: 124
A32: 11 | B32: 30/06/2025 | C32: ΜΙΣΘΟΔ.06 | D32: Μισθοδοσία μηνός (μικτά, εργοδοτικές, κρατήσεις) | E32: 60.00 | F32: =IFERROR(INDEX('Σχέδιο Λογαριασμών'!$B$5:$B$40,MATCH(E32,'Σχέδιο Λογαριασμών'!$A$5:$A$40,0)),"") -> Αμοιβές έμμισθου προσωπικού | G32: 1500
E33: 60.03 | F33: =IFERROR(INDEX('Σχέδιο Λογαριασμών'!$B$5:$B$40,MATCH(E33,'Σχέδιο Λογαριασμών'!$A$5:$A$40,0)),"") -> Εργοδοτικές εισφορές | G33: 300
E34: 55.00 | F34: =IFERROR(INDEX('Σχέδιο Λογαριασμών'!$B$5:$B$40,MATCH(E34,'Σχέδιο Λογαριασμών'!$A$5:$A$40,0)),"") -> Ασφαλιστικοί οργανισμοί (ΕΦΚΑ) | H34: 500
E35: 53.00 | F35: =IFERROR(INDEX('Σχέδιο Λογαριασμών'!$B$5:$B$40,MATCH(E35,'Σχέδιο Λογαριασμών'!$A$5:$A$40,0)),"") -> Αποδοχές προσωπικού πληρωτέες | H35: 1300
A36: 12 | B36: 30/06/2025 | C36: ΠΙΝ.ΑΠΟΣΒ. | D36: Μηνιαία απόσβεση εξοπλισμού (ραφιών) | E36: 66.00 | F36: =IFERROR(INDEX('Σχέδιο Λογαριασμών'!$B$5:$B$40,MATCH(E36,'Σχέδιο Λογαριασμών'!$A$5:$A$40,0)),"") -> Αποσβέσεις παγίων | G36: 33.33
E37: 14.00 | F37: =IFERROR(INDEX('Σχέδιο Λογαριασμών'!$B$5:$B$40,MATCH(E37,'Σχέδιο Λογαριασμών'!$A$5:$A$40,0)),"") -> Έπιπλα και λοιπός εξοπλισμός | H37: 33.33
A38: 13 | B38: 30/06/2025 | C38: Ζ-report | D38: Επιπλέον λιανική πώληση μετρητοίς με ΦΠΑ 24% | E38: 38.00 | F38: =IFERROR(INDEX('Σχέδιο Λογαριασμών'!$B$5:$B$40,MATCH(E38,'Σχέδιο Λογαριασμών'!$A$5:$A$40,0)),"") -> Ταμείο | G38: 1240
E39: 70.00 | F39: =IFERROR(INDEX('Σχέδιο Λογαριασμών'!$B$5:$B$40,MATCH(E39,'Σχέδιο Λογαριασμών'!$A$5:$A$40,0)),"") -> Πωλήσεις εμπορευμάτων | H39: 1000
E40: 54.00 | F40: =IFERROR(INDEX('Σχέδιο Λογαριασμών'!$B$5:$B$40,MATCH(E40,'Σχέδιο Λογαριασμών'!$A$5:$A$40,0)),"") -> Φ.Π.Α. | H40: 240
A41: 14 | B41: 01/07/2025 | C41: EXTRAIT | D41: Πληρωμή καθαρής μισθοδοσίας εργαζομένου (κλείνει 53.00) | E41: 53.00 | F41: =IFERROR(INDEX('Σχέδιο Λογαριασμών'!$B$5:$B$40,MATCH(E41,'Σχέδιο Λογαριασμών'!$A$5:$A$40,0)),"") -> Αποδοχές προσωπικού πληρωτέες | G41: 1300
...

Sheet Ισοζύγιο
A1: ΙΣΟΖΥΓΙΟ ΛΟΓΑΡΙΑΣΜΩΝ
A2: Αθροίζει αυτόματα το Ημερολόγιο (SUMIFS) • Τα σύνολα των δύο πλευρών πρέπει να είναι ίσα
A4: Κωδικός | B4: Λογαριασμός | C4: Σύνολο Χρέωσης | D4: Σύνολο Πίστωσης | E4: Χρεωστικό Υπόλοιπο | F4: Πιστωτικό Υπόλοιπο
A5: 10.00 | B5: Εδαφικές εκτάσεις (Γήπεδα-Οικόπεδα) | C5: =SUMIFS(Ημερολόγιο!$G$5:$G$64,Ημερολόγιο!$E$5:$E$64,A5) -> 0 | D5: =SUMIFS(Ημερολόγιο!$H$5:$H$64,Ημερολόγιο!$E$5:$E$64,A5) -> 0 | E5: =IF(C5-D5>0,C5-D5,0) -> 0 | F5: =IF(D5-C5>0,D5-C5,0) -> 0
A6: 11.00 | B6: Κτίρια - Εγκαταστάσεις κτιρίων | C6: =SUMIFS(Ημερολόγιο!$G$5:$G$64,Ημερολόγιο!$E$5:$E$64,A6) -> 0 | D6: =SUMIFS(Ημερολόγιο!$H$5:$H$64,Ημερολόγιο!$E$5:$E$64,A6) -> 0 | E6: =IF(C6-D6>0,C6-D6,0) -> 0 | F6: =IF(D6-C6>0,D6-C6,0) -> 0
A7: 12.00 | B7: Μηχανήματα - Τεχνικές εγκαταστάσεις | C7: =SUMIFS(Ημερολόγιο!$G$5:$G$64,Ημερολόγιο!$E$5:$E$64,A7) -> 0 | D7: =SUMIFS(Ημερολόγιο!$H$5:$H$64,Ημερολόγιο!$E$5:$E$64,A7) -> 0 | E7: =IF(C7-D7>0,C7-D7,0) -> 0 | F7: =IF(D7-C7>0,D7-C7,0) -> 0
A8: 13.00 | B8: Μεταφορικά μέσα | C8: =SUMIFS(Ημερολόγιο!$G$5:$G$64,Ημερολόγιο!$E$5:$E$64,A8) -> 0 | D8: =SUMIFS(Ημερολόγιο!$H$5:$H$64,Ημερολόγιο!$E$5:$E$64,A8) -> 0 | E8: =IF(C8-D8>0,C8-D8,0) -> 0 | F8: =IF(D8-C8>0,D8-C8,0) -> 0
A9: 14.00 | B9: Έπιπλα και λοιπός εξοπλισμός | C9: =SUMIFS(Ημερολόγιο!$G$5:$G$64,Ημερολόγιο!$E$5:$E$64,A9) -> 2000 | D9: =SUMIFS(Ημερολόγιο!$H$5:$H$64,Ημερολόγιο!$E$5:$E$64,A9) -> 33.33 | E9: =IF(C9-D9>0,C9-D9,0) -> 1966.67 | F9: =IF(D9-C9>0,D9-C9,0) -> 0
A10: 16.00 | B10: Ασώματες ακινητοποιήσεις (άυλα) | C10: =SUMIFS(Ημερολόγιο!$G$5:$G$64,Ημερολόγιο!$E$5:$E$64,A10) -> 0 | D10: =SUMIFS(Ημερολόγιο!$H$5:$H$64,Ημερολόγιο!$E$5:$E$64,A10) -> 0 | E10: =IF(C10-D10>0,C10-D10,0) -> 0 | F10: =IF(D10-C10>0,D10-C10,0) -> 0
A11: 20.00 | B11: Εμπορεύματα | C11: =SUMIFS(Ημερολόγιο!$G$5:$G$64,Ημερολόγιο!$E$5:$E$64,A11) -> 10000 | D11: =SUMIFS(Ημερολόγιο!$H$5:$H$64,Ημερολόγιο!$E$5:$E$64,A11) -> 0 | E11: =IF(C11-D11>0,C11-D11,0) -> 10000 | F11: =IF(D11-C11>0,D11-C11,0) -> 0
A12: 24.00 | B12: Πρώτες & βοηθητικές ύλες | C12: =SUMIFS(Ημερολόγιο!$G$5:$G$64,Ημερολόγιο!$E$5:$E$64,A12) -> 0 | D12: =SUMIFS(Ημερολόγιο!$H$5:$H$64,Ημερολόγιο!$E$5:$E$64,A12) -> 0 | E12: =IF(C12-D12>0,C12-D12,0) -> 0 | F12: =IF(D12-C12>0,D12-C12,0) -> 0
A13: 30.00 | B13: Πελάτες | C13: =SUMIFS(Ημερολόγιο!$G$5:$G$64,Ημερολόγιο!$E$5:$E$64,A13) -> 9920 | D13: =SUMIFS(Ημερολόγιο!$H$5:$H$64,Ημερολόγιο!$E$5:$E$64,A13) -> 9920 | E13: =IF(C13-D13>0,C13-D13,0) -> 0 | F13: =IF(D13-C13>0,D13-C13,0) -> 0
A14: 33.00 | B14: Χρεώστες διάφοροι | C14: =SUMIFS(Ημερολόγιο!$G$5:$G$64,Ημερολόγιο!$E$5:$E$64,A14) -> 0 | D14: =SUMIFS(Ημερολόγιο!$H$5:$H$64,Ημερολόγιο!$E$5:$E$64,A14) -> 0 | E14: =IF(C14-D14>0,C14-D14,0) -> 0 | F14: =IF(D14-C14>0,D14-C14,0) -> 0
A15: 38.00 | B15: Ταμείο | C15: =SUMIFS(Ημερολόγιο!$G$5:$G$64,Ημερολόγιο!$E$5:$E$64,A15) -> 9960 | D15: =SUMIFS(Ημερολόγιο!$H$5:$H$64,Ημερολόγιο!$E$5:$E$64,A15) -> 924 | E15: =IF(C15-D15>0,C15-D15,0) -> 9036 | F15: =IF(D15-C15>0,D15-C15,0) -> 0
A16: 38.03 | B16: Καταθέσεις όψεως (Τράπεζα) | C16: =SUMIFS(Ημερολόγιο!$G$5:$G$64,Ημερολόγιο!$E$5:$E$64,A16) -> 29920 | D16: =SUMIFS(Ημερολόγιο!$H$5:$H$64,Ημερολόγιο!$E$5:$E$64,A16) -> 13700 | E16: =IF(C16-D16>0,C16-D16,0) -> 16220 | F16: =IF(D16-C16>0,D16-C16,0) -> 0
... A40: 86.00 | B40: Αποτελέσματα χρήσεως | C40: =SUMIFS(Ημερολόγιο!$G$5:$G$64,Ημερολόγιο!$E$5:$E$64,A40) -> 0 | D40: =SUMIFS(Ημερολόγιο!$H$5:$H$64,Ημερολόγιο!$E$5:$E$64,A40) -> 0 | E40: =IF(C40-D40>0,C40-D40,0) -> 0 | F40: =IF(D40-C40>0,D40-C40,0) -> 0
B41: ΣΥΝΟΛΑ | C41: =SUM(C5:C40) -> 81757.33 | D41: =SUM(D5:D40) -> 81757.33 | E41: =SUM(E5:E40) -> 40600 | F41: =SUM(F5:F40) -> 40600
B42: Έλεγχος 1: Σ.Χρέωσης = Σ.Πίστωσης | C42: =IF(ROUND(C41-D41,2)=0,"✓ ΟΚ","✗ "&TEXT(C41-D41,"0.00")) -> ✓ ΟΚ
B43: Έλεγχος 2: Χρεωστ. Υπόλ. = Πιστωτ. Υπόλ. | E43: =IF(ROUND(E41-F41,2)=0,"✓ ΙΣΟΣΚΕΛΙΖΕΙ","✗ "&TEXT(E41-F41,"0.00")) -> ✓ ΙΣΟΣΚΕΛΙΖΕΙ

Sheet Καθολικό (Τ)
A1: ΚΑΘΟΛΙΚΟ — μορφή «Τ»
A2: Κάθε λογαριασμός: αριστερά η Χρέωση, δεξιά η Πίστωση, κάτω το Υπόλοιπο (όλα αυτόματα)
A4: ="38.00 "&IFERROR(INDEX('Σχέδιο Λογαριασμών'!$B$5:$B$40,MATCH("38.00",'Σχέδιο Λογαριασμών'!$A$5:$A$40,0)),"") -> 38.00 Ταμείο | D4: ="38.03 "&IFERROR(INDEX('Σχέδιο Λογαριασμών'!$B$5:$B$40,MATCH("38.03",'Σχέδιο Λογαριασμών'!$A$5:$A$40,0)),"") -> 38.03 Καταθέσεις όψεως (Τράπεζα)
A5: Χρέωση (+) | B5: Πίστωση (−) | D5: Χρέωση (+) | E5: Πίστωση (−)
A6: =SUMIFS(Ημερολόγιο!$G$5:$G$64,Ημερολόγιο!$E$5:$E$64,"38.00") -> 9960 | B6: =SUMIFS(Ημερολόγιο!$H$5:$H$64,Ημερολόγιο!$E$5:$E$64,"38.00") -> 924 | D6: =SUMIFS(Ημερολόγιο!$G$5:$G$64,Ημερολόγιο!$E$5:$E$64,"38.03") -> 29920 | E6: =SUMIFS(Ημερολόγιο!$H$5:$H$64,Ημερολόγιο!$E$5:$E$64,"38.03") -> 13700
A7: ="Υπόλοιπο: "&TEXT(ABS(A6-B6),"#,##0.00")&" € "&IF(A6-B6>0,"(Χρεωστικό)",IF(B6-A6>0,"(Πιστωτικό)","(Μηδέν)")) -> Υπόλοιπο: 9,036.00 € (Χρεωστικό) | D7: ="Υπόλοιπο: "&TEXT(ABS(D6-E6),"#,##0.00")&" € "&IF(D6-E6>0,"(Χρεωστικό)",IF(E6-D6>0,"(Πιστωτικό)","(Μηδέν)")) -> Υπόλοιπο: 16,220.00 € (Χρεωστικό)
A9: ="30.00 "&IFERROR(INDEX('Σχέδιο Λογαριασμών'!$B$5:$B$40,MATCH("30.00",'Σχέδιο Λογαριασμών'!$A$5:$A$40,0)),"") -> 30.00 Πελάτες | D9: ="50.00 "&IFERROR(INDEX('Σχέδιο Λογαριασμών'!$B$5:$B$40,MATCH("50.00",'Σχέδιο Λογαριασμών'!$A$5:$A$40,0)),"") -> 50.00 Προμηθευτές
A10: Χρέωση (+) | B10: Πίστωση (−) | D10: Χρέωση (+) | E10: Πίστωση (−)
A11: =SUMIFS(Ημερολόγιο!$G$5:$G$64,Ημερολόγιο!$E$5:$E$64,"30.00") -> 9920 | B11: =SUMIFS(Ημερολόγιο!$H$5:$H$64,Ημερολόγιο!$E$5:$E$64,"30.00") -> 9920 | D11: =SUMIFS(Ημερολόγιο!$G$5:$G$64,Ημερολόγιο!$E$5:$E$64,"50.00") -> 12400 | E11: =SUMIFS(Ημερολόγιο!$H$5:$H$64,Ημερολόγιο!$E$5:$E$64,"50.00") -> 15500
A12: ="Υπόλοιπο: "&TEXT(ABS(A11-B11),"#,##0.00")&" € "&IF(A11-B11>0,"(Χρεωστικό)",IF(B11-A11>0,"(Πιστωτικό)","(Μηδέν)")) -> Υπόλοιπο: 0.00 € (Μηδέν) | D12: ="Υπόλοιπο: "&TEXT(ABS(D11-E11),"#,##0.00")&" € "&IF(D11-E11>0,"(Χρεωστικό)",IF(E11-D11>0,"(Πιστωτικό)","(Μηδέν)")) -> Υπόλοιπο: 3,100.00 € (Πιστωτικό)
A14: ="54.00 "&IFERROR(INDEX('Σχέδιο Λογαριασμών'!$B$5:$B$40,MATCH("54.00",'Σχέδιο Λογαριασμών'!$A$5:$A$40,0)),"") -> 54.00 Φ.Π.Α. | D14: ="70.00 "&IFERROR(INDEX('Σχέδιο Λογαριασμών'!$B$5:$B$40,MATCH("70.00",'Σχέδιο Λογαριασμών'!$A$5:$A$40,0)),"") -> 70.00 Πωλήσεις εμπορευμάτων
A15: Χρέωση (+) | B15: Πίστωση (−) | D15: Χρέωση (+) | E15: Πίστωση (−)
A16: =SUMIFS(Ημερολόγιο!$G$5:$G$64,Ημερολόγιο!$E$5:$E$64,"54.00") -> 3024 | B16: =SUMIFS(Ημερολόγιο!$H$5:$H$64,Ημερολόγιο!$E$5:$E$64,"54.00") -> 2880 | D16: =SUMIFS(Ημερολόγιο!$G$5:$G$64,Ημερολόγιο!$E$5:$E$64,"70.00") -> 0 | E16: =SUMIFS(Ημερολόγιο!$H$5:$H$64,Ημερολόγιο!$E$5:$E$64,"70.00") -> 12000
A17: ="Υπόλοιπο: "&TEXT(ABS(A16-B16),"#,##0.00")&" € "&IF(A16-B16>0,"(Χρεωστικό)",IF(B16-A16>0,"(Πιστωτικό)","(Μηδέν)")) -> Υπόλοιπο: 144.00 € (Χρεωστικό) | D17: ="Υπόλοιπο: "&TEXT(ABS(D16-E16),"#,##0.00")&" € "&IF(D16-E16>0,"(Χρεωστικό)",IF(E16-D16>0,"(Πιστωτικό)","(Μηδέν)")) -> Υπόλοιπο: 12,000.00 € (Πιστωτικό)
A19: ="20.00 "&IFERROR(INDEX('Σχέδιο Λογαριασμών'!$B$5:$B$40,MATCH("20.00",'Σχέδιο Λογαριασμών'!$A$5:$A$40,0)),"") -> 20.00 Εμπορεύματα | D19: ="60.00 "&IFERROR(INDEX('Σχέδιο Λογαριασμών'!$B$5:$B$40,MATCH("60.00",'Σχέδιο Λογαριασμών'!$A$5:$A$40,0)),"") -> 60.00 Αμοιβές έμμισθου προσωπικού
A20: Χρέωση (+) | B20: Πίστωση (−) | D20: Χρέωση (+) | E20: Πίστωση (−)
A21: =SUMIFS(Ημερολόγιο!$G$5:$G$64,Ημερολόγιο!$E$5:$E$64,"20.00") -> 10000 | B21: =SUMIFS(Ημερολόγιο!$H$5:$H$64,Ημερολόγιο!$E$5:$E$64,"20.00") -> 0 | D21: =SUMIFS(Ημερολόγιο!$G$5:$G$64,Ημερολόγιο!$E$5:$E$64,"60.00") -> 1500 | E21: =SUMIFS(Ημερολόγιο!$H$5:$H$64,Ημερολόγιο!$E$5:$E$64,"60.00") -> 0
A22: ="Υπόλοιπο: "&TEXT(ABS(A21-B21),"#,##0.00")&" € "&IF(A21-B21>0,"(Χρεωστικό)",IF(B21-A21>0,"(Πιστωτικό)","(Μηδέν)")) -> Υπόλοιπο: 10,000.00 € (Χρεωστικό) | D22: ="Υπόλοιπο: "&TEXT(ABS(D21-E21),"#,##0.00")&" € "&IF(D21-E21>0,"(Χρεωστικό)",IF(E21-D21>0,"(Πιστωτικό)","(Μηδέν)")) -> Υπόλοιπο: 1,500.00 € (Χρεωστικό)

Sheet Ασκήσεις
A1: ΑΣΚΗΣΕΙΣ — κάνε τις εγγραφές μόνος σου
A2: Σκέψου: ποιος λογαριασμός χρεώνεται, ποιος πιστώνεται; Λύσεις στο κάτω μέρος.
A4: 1) Αγορά εμπορευμάτων αξίας 4.000 € + ΦΠΑ 24% από προμηθευτή, επί πιστώσει.
A9: 2) Λιανική πώληση 1.000 € + ΦΠΑ 24% με μετρητά.
A14: 3) Πληρωμή ενοικίου 600 € (χωρίς ΦΠΑ) μέσω τράπεζας.
A19: 4) Είσπραξη 2.480 € από πελάτη στο ταμείο.
A24: 5) Αγορά Η/Υ αξίας 1.200 € + ΦΠΑ 24%, επί πιστώσει.
A29: ΛΥΣΕΙΣ
A30: 1) Χ 20.00 Εμπορεύματα 4.000 | Χ 54.00 ΦΠΑ 960 /// Π 50.00 Προμηθευτές 4.960
A31: 2) Χ 38.00 Ταμείο 1.240 /// Π 70.00 Πωλήσεις 1.000 | Π 54.00 ΦΠΑ 240
A32: 3) Χ 62.04 Ενοίκια 600 /// Π 38.03 Καταθέσεις όψεως 600
A33: 4) Χ 38.00 Ταμείο 2.480 /// Π 30.00 Πελάτες 2.480
... A35: Χ = Χρέωση, Π = Πίστωση. Το /// χωρίζει τη χρεωστική από την πιστωτική πλευρά της εγγραφής.

Sheet Αποτελέσματα-Ισολογισμός
A1: ΚΑΤΑΣΤΑΣΗ ΑΠΟΤΕΛΕΣΜΑΤΩΝ & ΙΣΟΛΟΓΙΣΜΟΣ
A2: Συνδέεται ΖΩΝΤΑΝΑ με το Ισοζύγιο. Άλλαξε ποσά στο Ημερολόγιο και όλα ενημερώνονται αυτόματα.
A4: Α) ΚΑΤΑΣΤΑΣΗ ΑΠΟΤΕΛΕΣΜΑΤΩΝ ΧΡΗΣΗΣ
A5: Κωδ. | B5: Λογαριασμός | C5: Ποσό
B6: ΕΣΟΔΑ (Κύκλος εργασιών)
A7: 70.00 | B7: Πωλήσεις εμπορευμάτων | C7: =Ισοζύγιο!F35 -> 12000
A8: 71.00 | B8: Πωλήσεις προϊόντων | C8: =Ισοζύγιο!F36 -> 0
A9: 73.00 | B9: Έσοδα παροχής υπηρεσιών | C9: =Ισοζύγιο!F37 -> 0
A10: 76.00 | B10: Έσοδα κεφαλαίων (τόκοι) | C10: =Ισοζύγιο!F38 -> 0
B11: Σύνολο Εσόδων | C11: =SUM(C7:C10) -> 12000
B13: ΕΞΟΔΑ (κατ' είδος)
A14: 60.00 | B14: Αμοιβές έμμισθου προσωπικού | C14: =Ισοζύγιο!E26 -> 1500
A15: 60.03 | B15: Εργοδοτικές εισφορές | C15: =Ισοζύγιο!E27 -> 300
A16: 61.00 | B16: Αμοιβές & έξοδα τρίτων | C16: =Ισοζύγιο!E28 -> 0
A17: 62.03 | B17: Τηλεπικοινωνίες | C17: =Ισοζύγιο!E29 -> 100
A18: 62.04 | B18: Ενοίκια | C18: =Ισοζύγιο!E30 -> 800
A19: 62.98 | B19: Λοιπές παροχές (ΔΕΗ/ύδρευση) | C19: =Ισοζύγιο!E31 -> 500
A20: 64.00 | B20: Έξοδα μεταφορών | C20: =Ισοζύγιο!E32 -> 0
A21: 64.07 | B21: Έντυπα & γραφική ύλη | C21: =Ισοζύγιο!E33 -> 0
A22: 66.00 | B22: Αποσβέσεις παγίων | C22: =Ισοζύγιο!E34 -> 33.33
B23: Σύνολο Εξόδων | C23: =SUM(C14:C22) -> 3233.33
B24: ΑΠΟΤΕΛΕΣΜΑ ΧΡΗΣΗΣ (Κέρδος / Ζημία) | C24: =C11-C23 -> 8766.67
B25: (θετικό = Κέρδος · αρνητικό = Ζημία)
A28: Β) ΙΣΟΛΟΓΙΣΜΟΣ (τέλους χρήσης)
A29: Κωδ. | B29: ΕΝΕΡΓΗΤΙΚΟ | C29: Ποσό | D29: Κωδ. | E29: ΠΑΘΗΤΙΚΟ & ΚΑΘΑΡΗ ΘΕΣΗ | F29: Ποσό
A30: 10.00 | B30: Γήπεδα-Οικόπεδα | C30: =Ισοζύγιο!E5 -> 0 | D30: 40.00 | E30: Κεφάλαιο | F30: =Ισοζύγιο!F17 -> 25000
A31: 11.00 | B31: Κτίρια | C31: =Ισοζύγιο!E6 -> 0 | D31: 41.00 | E31: Αποθεματικά | F31: =Ισοζύγιο!F18 -> 0
A32: 12.00 | B32: Μηχανήματα | C32: =Ισοζύγιο!E7 -> 0 | D32: 42.00 | E32: Αποτελέσματα εις νέο | F32: =Ισοζύγιο!F19 -> 0
A33: 13.00 | B33: Μεταφορικά μέσα | C33: =Ισοζύγιο!E8 -> 0 | D33: 45.00 | E33: Μακροπρ. υποχρεώσεις | F33: =Ισοζύγιο!F20 -> 0
A34: 14.00 | B34: Έπιπλα & εξοπλισμός | C34: =Ισοζύγιο!E9 -> 1966.67 | D34: 50.00 | E34: Προμηθευτές | F34: =Ισοζύγιο!F21 -> 3100
A35: 16.00 | B35: Άυλα | C35: =Ισοζύγιο!E10 -> 0 | D35: 53.00 | E35: Αποδοχές πληρωτέες | F35: =Ισοζύγιο!F22 -> 0
A36: 20.00 | B36: Εμπορεύματα | C36: =Ισοζύγιο!E11 -> 10000 | D36: 54.00 | E36: ΦΠΑ αποδοτέος | F36: =Ισοζύγιο!F23 -> 0
A37: 24.00 | B37: Πρώτες ύλες | C37: =Ισοζύγιο!E12 -> 0 | D37: 54.03 | E37: ΦΜΥ | F37: =Ισοζύγιο!F24 -> 0
A38: 30.00 | B38: Πελάτες | C38: =Ισοζύγιο!E13 -> 0 | D38: 55.00 | E38: ΕΦΚΑ | F38: =Ισοζύγιο!F25 -> 500
A39: 33.00 | B39: Χρεώστες διάφοροι | C39: =Ισοζύγιο!E14 -> 0 | D39: 86.00 | E39: Αποτέλεσμα χρήσης (Κέρδος/Ζημία) | F39: =C24 -> 8766.67
A40: 54.00 | B40: ΦΠΑ εισπρακτέος (αν χρεωστικό) | C40: =Ισοζύγιο!E23 -> 144
A41: 38.00 | B41: Ταμείο | C41: =Ισοζύγιο!E15 -> 9036
A42: 38.03 | B42: Καταθέσεις όψεως | C42: =Ισοζύγιο!E16 -> 16220
B44: ΣΥΝΟΛΟ ΕΝΕΡΓΗΤΙΚΟΥ | C44: =SUM(C30:C42) -> 37366.67 | E44: ΣΥΝΟΛΟ ΠΑΘΗΤΙΚΟΥ & Κ.Θ. | F44: =SUM(F30:F39) -> 37366.67
A45: =IF(ROUND(C44-F44,2)=0,"✓ ΙΣΟΣΚΕΛΙΖΕΙ: ΕΝΕΡΓΗΤΙΚΟ = ΠΑΘΗΤΙΚΟ + ΚΑΘΑΡΗ ΘΕΣΗ","✗ ΔΙΑΦΟΡΑ "&TEXT(C44-F44,"0.00")&" € — έλεγξε το Ημερολόγιο") -> ✓ ΙΣΟΣΚΕΛΙΖΕΙ: ΕΝΕΡΓΗΤΙΚΟ = ΠΑΘΗΤΙΚΟ + ΚΑΘΑΡΗ ΘΕΣΗ
...
